[2024-04-22T09:58:46.791+0000] {local_task_job_runner.py:120} INFO - ::group::Pre task execution logs
[2024-04-22T09:58:46.874+0000] {taskinstance.py:2073} INFO - Dependencies all met for dep_context=non-requeueable deps ti=<TaskInstance: etl.create_table manual__2024-04-22T09:58:43.196533+00:00 [queued]>
[2024-04-22T09:58:46.894+0000] {taskinstance.py:2073} INFO - Dependencies all met for dep_context=requeueable deps ti=<TaskInstance: etl.create_table manual__2024-04-22T09:58:43.196533+00:00 [queued]>
[2024-04-22T09:58:46.894+0000] {taskinstance.py:2303} INFO - Starting attempt 1 of 1
[2024-04-22T09:58:46.937+0000] {taskinstance.py:2327} INFO - Executing <Task(PythonOperator): create_table> on 2024-04-22 09:58:43.196533+00:00
[2024-04-22T09:58:46.953+0000] {logging_mixin.py:188} WARNING - /home/***/.local/lib/python3.12/site-packages/***/task/task_runner/standard_task_runner.py:61 DeprecationWarning: This process (pid=12857) is multi-threaded, use of fork() may lead to deadlocks in the child.
[2024-04-22T09:58:46.954+0000] {standard_task_runner.py:63} INFO - Started process 12877 to run task
[2024-04-22T09:58:46.957+0000] {standard_task_runner.py:90} INFO - Running: ['***', 'tasks', 'run', 'etl', 'create_table', 'manual__2024-04-22T09:58:43.196533+00:00', '--job-id', '15', '--raw', '--subdir', 'DAGS_FOLDER/etl.py', '--cfg-path', '/tmp/tmpip_oboqq']
[2024-04-22T09:58:46.960+0000] {standard_task_runner.py:91} INFO - Job 15: Subtask create_table
[2024-04-22T09:58:47.017+0000] {task_command.py:426} INFO - Running <TaskInstance: etl.create_table manual__2024-04-22T09:58:43.196533+00:00 [running]> on host b6fcd665afc9
[2024-04-22T09:58:47.122+0000] {taskinstance.py:2644} INFO - Exporting env vars: AIRFLOW_CTX_DAG_OWNER='***' AIRFLOW_CTX_DAG_ID='etl' AIRFLOW_CTX_TASK_ID='create_table' AIRFLOW_CTX_EXECUTION_DATE='2024-04-22T09:58:43.196533+00:00' AIRFLOW_CTX_TRY_NUMBER='1' AIRFLOW_CTX_DAG_RUN_ID='manual__2024-04-22T09:58:43.196533+00:00'
[2024-04-22T09:58:47.124+0000] {taskinstance.py:430} INFO - ::endgroup::
[2024-04-22T09:58:47.134+0000] {taskinstance.py:441} INFO - ::group::Post task execution logs
[2024-04-22T09:58:47.142+0000] {taskinstance.py:2890} ERROR - Task failed with exception
Traceback (most recent call last):
  File "/home/airflow/.local/lib/python3.12/site-packages/airflow/models/taskinstance.py", line 465, in _execute_task
    result = _execute_callable(context=context, **execute_callable_kwargs)
             ^^^^^^^^^^^^^^^^^^^^^^^^^^^^^^^^^^^^^^^^^^^^^^^^^^^^^^^^^^^^^
  File "/home/airflow/.local/lib/python3.12/site-packages/airflow/models/taskinstance.py", line 432, in _execute_callable
    return execute_callable(context=context, **execute_callable_kwargs)
           ^^^^^^^^^^^^^^^^^^^^^^^^^^^^^^^^^^^^^^^^^^^^^^^^^^^^^^^^^^^^
  File "/home/airflow/.local/lib/python3.12/site-packages/airflow/models/baseoperator.py", line 400, in wrapper
    return func(self, *args, **kwargs)
           ^^^^^^^^^^^^^^^^^^^^^^^^^^^
  File "/home/airflow/.local/lib/python3.12/site-packages/airflow/operators/python.py", line 235, in execute
    return_value = self.execute_callable()
                   ^^^^^^^^^^^^^^^^^^^^^^^
  File "/home/airflow/.local/lib/python3.12/site-packages/airflow/operators/python.py", line 252, in execute_callable
    return self.python_callable(*self.op_args, **self.op_kwargs)
           ^^^^^^^^^^^^^^^^^^^^^^^^^^^^^^^^^^^^^^^^^^^^^^^^^^^^^
  File "/opt/airflow/dags/etl.py", line 33, in _create_tables
    conn = hook.get_conn()
           ^^^^^^^^^^^^^^^
  File "/home/airflow/.local/lib/python3.12/site-packages/airflow/providers/postgres/hooks/postgres.py", line 131, in get_conn
    conn = deepcopy(self.connection or self.get_connection(conn_id))
                                       ^^^^^^^^^^^^^^^^^^^^^^^^^^^^
  File "/home/airflow/.local/lib/python3.12/site-packages/airflow/hooks/base.py", line 83, in get_connection
    conn = Connection.get_connection_from_secrets(conn_id)
           ^^^^^^^^^^^^^^^^^^^^^^^^^^^^^^^^^^^^^^^^^^^^^^^
  File "/home/airflow/.local/lib/python3.12/site-packages/airflow/models/connection.py", line 519, in get_connection_from_secrets
    raise AirflowNotFoundException(f"The conn_id `{conn_id}` isn't defined")
airflow.exceptions.AirflowNotFoundException: The conn_id `my_postgres` isn't defined
[2024-04-22T09:58:47.154+0000] {taskinstance.py:1205} INFO - Marking task as FAILED. dag_id=etl, task_id=create_table, execution_date=20240422T095843, start_date=20240422T095846, end_date=20240422T095847
[2024-04-22T09:58:47.172+0000] {standard_task_runner.py:110} ERROR - Failed to execute job 15 for task create_table (The conn_id `my_postgres` isn't defined; 12877)
[2024-04-22T09:58:47.214+0000] {local_task_job_runner.py:240} INFO - Task exited with return code 1
[2024-04-22T09:58:47.240+0000] {taskinstance.py:3482} INFO - 0 downstream tasks scheduled from follow-on schedule check
[2024-04-22T09:58:47.253+0000] {local_task_job_runner.py:222} INFO - ::endgroup::
